Workbook

Sheet 팀배정_전체
A1: No | B1: 팀 | C1: 이름 | D1: 학번 | E1: 성별 | F1: 티셔츠 | G1: 출발지 | H1: 식단 제약 | I1: 친구 요청(원문) | J1: 친구그룹 | K1: 명단 대조 | L1: 친구그룹 검증
A2: 1 | B2: JOY | C2: Abdallah Alhamidi | D2: 2026318827 | E2: M | F2: L | G2: Suwon | H2: No pork | K2: =IF(COUNTIF('팀별_명단'!$A$5:$W$34,$C2)=1,"OK","확인") -> OK | L2: =IF($J2="","-",IF(COUNTIFS($J$2:$J$171,$J2,$B$2:$B$171,$B2)=COUNTIF($J$2:$J$171,$J2),"OK","확인")) -> -
A3: 2 | B3: JOY | C3: Alberto Gil Carvalho | D3: 2026319184 | E3: M | F3: M | G3: Suwon | I3: Rafael Cunha, Beatriz Costa, Ines | J3: 143 | K3: =IF(COUNTIF('팀별_명단'!$A$5:$W$34,$C3)=1,"OK","확인") -> OK | L3: =IF($J3="","-",IF(COUNTIFS($J$2:$J$171,$J3,$B$2:$B$171,$B3)=COUNTIF($J$2:$J$171,$J3),"OK","확인")) -> OK
A4: 3 | B4: JOY | C4: Alexandra Becker | D4: 2026318952 | E4: F | F4: L | G4: Seoul | K4: =IF(COUNTIF('팀별_명단'!$A$5:$W$34,$C4)=1,"OK","확인") -> OK | L4: =IF($J4="","-",IF(COUNTIFS($J$2:$J$171,$J4,$B$2:$B$171,$B4)=COUNTIF($J$2:$J$171,$J4),"OK","확인")) -> -
A5: 4 | B5: JOY | C5: Artyom Tsoy | D5: 2026319226 | E5: M | F5: L | G5: Suwon | I5: Peter Naur | J5: 138 | K5: =IF(COUNTIF('팀별_명단'!$A$5:$W$34,$C5)=1,"OK","확인") -> OK | L5: =IF($J5="","-",IF(COUNTIFS($J$2:$J$171,$J5,$B$2:$B$171,$B5)=COUNTIF($J$2:$J$171,$J5),"OK","확인")) -> OK
A6: 5 | B6: JOY | C6: Beatriz Costa | D6: 2026318588 | E6: F | F6: M | G6: Suwon | I6: Alberto Carvalho, Rafael Cunha, Ines | J6: 143 | K6: =IF(COUNTIF('팀별_명단'!$A$5:$W$34,$C6)=1,"OK","확인") -> OK | L6: =IF($J6="","-",IF(COUNTIFS($J$2:$J$171,$J6,$B$2:$B$171,$B6)=COUNTIF($J$2:$J$171,$J6),"OK","확인")) -> OK
A7: 6 | B7: JOY | C7: Ben Daniel Gerhard Murrmann | D7: 2026318926 | E7: M | F7: XL | G7: Seoul | I7: Luis | J7: 13 | K7: =IF(COUNTIF('팀별_명단'!$A$5:$W$34,$C7)=1,"OK","확인") -> OK | L7: =IF($J7="","-",IF(COUNTIFS($J$2:$J$171,$J7,$B$2:$B$171,$B7)=COUNTIF($J$2:$J$171,$J7),"OK","확인")) -> OK
A8: 7 | B8: JOY | C8: Boglarka Peter | D8: 2026319032 | E8: F | F8: S | G8: Seoul | K8: =IF(COUNTIF('팀별_명단'!$A$5:$W$34,$C8)=1,"OK","확인") -> OK | L8: =IF($J8="","-",IF(COUNTIFS($J$2:$J$171,$J8,$B$2:$B$171,$B8)=COUNTIF($J$2:$J$171,$J8),"OK","확인")) -> -
A9: 8 | B9: JOY | C9: Carla Mas Juncosa | D9: 2026318575 | E9: F | F9: L | G9: Seoul | J9: 102 | K9: =IF(COUNTIF('팀별_명단'!$A$5:$W$34,$C9)=1,"OK","확인") -> OK | L9: =IF($J9="","-",IF(COUNTIFS($J$2:$J$171,$J9,$B$2:$B$171,$B9)=COUNTIF($J$2:$J$171,$J9),"OK","확인")) -> OK
A10: 9 | B10: JOY | C10: Eeva Joensuu | D10: 2026318617 | E10: F | F10: L | G10: Seoul | I10: Ella Heikinheimo | J10: 24 | K10: =IF(COUNTIF('팀별_명단'!$A$5:$W$34,$C10)=1,"OK","확인") -> OK | L10: =IF($J10="","-",IF(COUNTIFS($J$2:$J$171,$J10,$B$2:$B$171,$B10)=COUNTIF($J$2:$J$171,$J10),"OK","확인")) -> OK
A11: 10 | B11: JOY | C11: Ella Heikinheimo | D11: 2026318726 | E11: F | F11: L | G11: Seoul | H11: No red meat | I11: Eeva Joensuu | J11: 24 | K11: =IF(COUNTIF('팀별_명단'!$A$5:$W$34,$C11)=1,"OK","확인") -> OK | L11: =IF($J11="","-",IF(COUNTIFS($J$2:$J$171,$J11,$B$2:$B$171,$B11)=COUNTIF($J$2:$J$171,$J11),"OK","확인")) -> OK
A12: 11 | B12: JOY | C12: Finesse Johnson Stewart | D12: 2026739005 | E12: F | F12: M | G12: Seoul | I12: Jalynn Hinton | J12: 84 | K12: =IF(COUNTIF('팀별_명단'!$A$5:$W$34,$C12)=1,"OK","확인") -> OK | L12: =IF($J12="","-",IF(COUNTIFS($J$2:$J$171,$J12,$B$2:$B$171,$B12)=COUNTIF($J$2:$J$171,$J12),"OK","확인")) -> OK
A13: 12 | B13: JOY | C13: Florian Schaal | D13: 2026318744 | E13: M | F13: M | G13: Seoul | K13: =IF(COUNTIF('팀별_명단'!$A$5:$W$34,$C13)=1,"OK","확인") -> OK | L13: =IF($J13="","-",IF(COUNTIFS($J$2:$J$171,$J13,$B$2:$B$171,$B13)=COUNTIF($J$2:$J$171,$J13),"OK","확인")) -> -
A14: 13 | B14: JOY | C14: Frida Siffring | D14: 2026318724 | E14: F | F14: 2XL | G14: Seoul | K14: =IF(COUNTIF('팀별_명단'!$A$5:$W$34,$C14)=1,"OK","확인") -> OK | L14: =IF($J14="","-",IF(COUNTIFS($J$2:$J$171,$J14,$B$2:$B$171,$B14)=COUNTIF($J$2:$J$171,$J14),"OK","확인")) -> -
A15: 14 | B15: JOY | C15: Giovanni Fragiacomo | D15: 2026318615 | E15: M | F15: M | G15: Suwon | K15: =IF(COUNTIF('팀별_명단'!$A$5:$W$34,$C15)=1,"OK","확인") -> OK | L15: =IF($J15="","-",IF(COUNTIFS($J$2:$J$171,$J15,$B$2:$B$171,$B15)=COUNTIF($J$2:$J$171,$J15),"OK","확인")) -> -
A16: 15 | B16: JOY | C16: Ines Goncalves | D16: 2026319210 | E16: F | F16: S | G16: Suwon | I16: Beatriz Costa, Rafael Cunha, Alberto | J16: 143 | K16: =IF(COUNTIF('팀별_명단'!$A$5:$W$34,$C16)=1,"OK","확인") -> OK | L16: =IF($J16="","-",IF(COUNTIFS($J$2:$J$171,$J16,$B$2:$B$171,$B16)=COUNTIF($J$2:$J$171,$J16),"OK","확인")) -> OK
A17: 16 | B17: JOY | C17: Isabella van der Kruk | D17: 2026318968 | E17: F | F17: L | G17: Seoul | K17: =IF(COUNTIF('팀별_명단'!$A$5:$W$34,$C17)=1,"OK","확인") -> OK | L17: =IF($J17="","-",IF(COUNTIFS($J$2:$J$171,$J17,$B$2:$B$171,$B17)=COUNTIF($J$2:$J$171,$J17),"OK","확인")) -> -
A18: 17 | B18: JOY | C18: Jalynn De'nea Hinton | D18: 2026739006 | E18: F | F18: M | G18: Seoul | I18: Finesse Johnson | J18: 84 | K18: =IF(COUNTIF('팀별_명단'!$A$5:$W$34,$C18)=1,"OK","확인") -> OK | L18: =IF($J18="","-",IF(COUNTIFS($J$2:$J$171,$J18,$B$2:$B$171,$B18)=COUNTIF($J$2:$J$171,$J18),"OK","확인")) -> OK
A19: 18 | B19: JOY | C19: Julian Kuehling | D19: 2026318967 | E19: M | F19: XL | G19: Seoul | K19: =IF(COUNTIF('팀별_명단'!$A$5:$W$34,$C19)=1,"OK","확인") -> OK | L19: =IF($J19="","-",IF(COUNTIFS($J$2:$J$171,$J19,$B$2:$B$171,$B19)=COUNTIF($J$2:$J$171,$J19),"OK","확인")) -> -
A20: 19 | B20: JOY | C20: Kamila Chaibi | D20: 2026319177 | E20: F | F20: S | G20: Suwon | H20: No pork | K20: =IF(COUNTIF('팀별_명단'!$A$5:$W$34,$C20)=1,"OK","확인") -> OK | L20: =IF($J20="","-",IF(COUNTIFS($J$2:$J$171,$J20,$B$2:$B$171,$B20)=COUNTIF($J$2:$J$171,$J20),"OK","확인")) -> -
A21: 20 | B21: JOY | C21: Luis Deckert | D21: 2026318979 | E21: M | F21: S | G21: Seoul | I21: Ben Murrmann | J21: 13 | K21: =IF(COUNTIF('팀별_명단'!$A$5:$W$34,$C21)=1,"OK","확인") -> OK | L21: =IF($J21="","-",IF(COUNTIFS($J$2:$J$171,$J21,$B$2:$B$171,$B21)=COUNTIF($J$2:$J$171,$J21),"OK","확인")) -> OK
A22: 21 | B22: JOY | C22: Matina Asgari | D22: 2026318887 | E22: F | F22: S | G22: Seoul | I22: Lisa Oelschlagel | K22: =IF(COUNTIF('팀별_명단'!$A$5:$W$34,$C22)=1,"OK","확인") -> OK | L22: =IF($J22="","-",IF(COUNTIFS($J$2:$J$171,$J22,$B$2:$B$171,$B22)=COUNTIF($J$2:$J$171,$J22),"OK","확인")) -> -
A23: 22 | B23: JOY | C23: Naira Yang | D23: 2026318808 | E23: F | F23: S | G23: Seoul | I23: Carla Mas Juncosa | J23: 102 | K23: =IF(COUNTIF('팀별_명단'!$A$5:$W$34,$C23)=1,"OK","확인") -> OK | L23: =IF($J23="","-",IF(COUNTIFS($J$2:$J$171,$J23,$B$2:$B$171,$B23)=COUNTIF($J$2:$J$171,$J23),"OK","확인")) -> OK
A24: 23 | B24: JOY | C24: Narandavaa Nyamdorj | D24: 2026319298 | E24: M | F24: L | G24: Suwon | K24: =IF(COUNTIF('팀별_명단'!$A$5:$W$34,$C24)=1,"OK","확인") -> OK | L24: =IF($J24="","-",IF(COUNTIFS($J$2:$J$171,$J24,$B$2:$B$171,$B24)=COUNTIF($J$2:$J$171,$J24),"OK","확인")) -> -
A25: 24 | B25: JOY | C25: Penru Minha | D25: 2026318884 | E25: F | F25: XL | G25: Seoul | K25: =IF(COUNTIF('팀별_명단'!$A$5:$W$34,$C25)=1,"OK","확인") -> OK | L25: =IF($J25="","-",IF(COUNTIFS($J$2:$J$171,$J25,$B$2:$B$171,$B25)=COUNTIF($J$2:$J$171,$J25),"OK","확인")) -> -
A26: 25 | B26: JOY | C26: Peter Moeller Naur | D26: 2026319200 | E26: M | F26: 2XL | G26: Suwon | I26: Theis Hove | J26: 138 | K26: =IF(COUNTIF('팀별_명단'!$A$5:$W$34,$C26)=1,"OK","확인") -> OK | L26: =IF($J26="","-",IF(COUNTIFS($J$2:$J$171,$J26,$B$2:$B$171,$B26)=COUNTIF($J$2:$J$171,$J26),"OK","확인")) -> OK
A27: 26 | B27: JOY | C27: Petra Tuunanen | D27: 2026318730 | E27: F | F27: 2XL | G27: Seoul | K27: =IF(COUNTIF('팀별_명단'!$A$5:$W$34,$C27)=1,"OK","확인") -> OK | L27: =IF($J27="","-",IF(COUNTIFS($J$2:$J$171,$J27,$B$2:$B$171,$B27)=COUNTIF($J$2:$J$171,$J27),"OK","확인")) -> -
A28: 27 | B28: JOY | C28: Rafael Cunha | D28: 2026319108 | E28: M | F28: M | G28: Suwon | I28: Alberto Carvalho, Beatriz Costa, Ines | J28: 143 | K28: =IF(COUNTIF('팀별_명단'!$A$5:$W$34,$C28)=1,"OK","확인") -> OK | L28: =IF($J28="","-",IF(COUNTIFS($J$2:$J$171,$J28,$B$2:$B$171,$B28)=COUNTIF($J$2:$J$171,$J28),"OK","확인")) -> OK
A29: 28 | B29: JOY | C29: Serafima Pavlova | D29: 2026318577 | E29: F | F29: L | G29: Seoul | K29: =IF(COUNTIF('팀별_명단'!$A$5:$W$34,$C29)=1,"OK","확인") -> OK | L29: =IF($J29="","-",IF(COUNTIFS($J$2:$J$171,$J29,$B$2:$B$171,$B29)=COUNTIF($J$2:$J$171,$J29),"OK","확인")) -> -
A30: 29 | B30: JOY | C30: Theis Oestergaard Hove | D30: 2026318814 | E30: M | F30: XL | G30: Suwon | J30: 138 | K30: =IF(COUNTIF('팀별_명단'!$A$5:$W$34,$C30)=1,"OK","확인") -> OK | L30: =IF($J30="","-",IF(COUNTIFS($J$2:$J$171,$J30,$B$2:$B$171,$B30)=COUNTIF($J$2:$J$171,$J30),"OK","확인")) -> OK
A31: 30 | B31: SADNESS | C31: Aaron Dumlao | D31: 2026318585 | E31: M | F31: L | G31: Suwon | J31: 141 | K31: =IF(COUNTIF('팀별_명단'!$A$5:$W$34,$C31)=1,"OK","확인") -> OK | L31: =IF($J31="","-",IF(COUNTIFS($J$2:$J$171,$J31,$B$2:$B$171,$B31)=COUNTIF($J$2:$J$171,$J31),"OK","확인")) -> OK
A32: 31 | B32: SADNESS | C32: Alessandro Noia | D32: 2026318573 | E32: M | F32: M | G32: Seoul | J32: 66 | K32: =IF(COUNTIF('팀별_명단'!$A$5:$W$34,$C32)=1,"OK","확인") -> OK | L32: =IF($J32="","-",IF(COUNTIFS($J$2:$J$171,$J32,$B$2:$B$171,$B32)=COUNTIF($J$2:$J$171,$J32),"OK","확인")) -> OK
A33: 32 | B33: SADNESS | C33: Alice Nicoli | D33: 2026318735 | E33: F | F33: M | G33: Seoul | I33: Alessandro Noia, Sofia Felicetti | J33: 66 | K33: =IF(COUNTIF('팀별_명단'!$A$5:$W$34,$C33)=1,"OK","확인") -> OK | L33: =IF($J33="","-",IF(COUNTIFS($J$2:$J$171,$J33,$B$2:$B$171,$B33)=COUNTIF($J$2:$J$171,$J33),"OK","확인")) -> OK
A34: 33 | B34: SADNESS | C34: Amber Mae Britchford | D34: 2026318156 | E34: F | F34: M | G34: Seoul | K34: =IF(COUNTIF('팀별_명단'!$A$5:$W$34,$C34)=1,"OK","확인") -> OK | L34: =IF($J34="","-",IF(COUNTIFS($J$2:$J$171,$J34,$B$2:$B$171,$B34)=COUNTIF($J$2:$J$171,$J34),"OK","확인")) -> -
A35: 34 | B35: SADNESS | C35: Anika Dartsch | D35: 2026318866 | E35: F | F35: M | G35: Seoul | I35: Lea Koric | J35: 67 | K35: =IF(COUNTIF('팀별_명단'!$A$5:$W$34,$C35)=1,"OK","확인") -> OK | L35: =IF($J35="","-",IF(COUNTIFS($J$2:$J$171,$J35,$B$2:$B$171,$B35)=COUNTIF($J$2:$J$171,$J35),"OK","확인")) -> OK
A36: 35 | B36: SADNESS | C36: Augustin Kuntz | D36: 2026319293 | E36: M | F36: M | G36: Seoul | K36: =IF(COUNTIF('팀별_명단'!$A$5:$W$34,$C36)=1,"OK","확인") -> OK | L36: =IF($J36="","-",IF(COUNTIFS($J$2:$J$171,$J36,$B$2:$B$171,$B36)=COUNTIF($J$2:$J$171,$J36),"OK","확인")) -> -
A37: 36 | B37: SADNESS | C37: Farouk Ousseini | D37: 2026318586 | E37: M | F37: L | G37: Seoul | H37: Halal | I37: Faruk Husovic | J37: 83 | K37: =IF(COUNTIF('팀별_명단'!$A$5:$W$34,$C37)=1,"OK","확인") -> OK | L37: =IF($J37="","-",IF(COUNTIFS($J$2:$J$171,$J37,$B$2:$B$171,$B37)=COUNTIF($J$2:$J$171,$J37),"OK","확인")) -> OK
A38: 37 | B38: SADNESS | C38: Faruk Husovic | D38: 2026319173 | E38: M | F38: L | G38: Seoul | I38: Farouk Ousseini | J38: 83 | K38: =IF(COUNTIF('팀별_명단'!$A$5:$W$34,$C38)=1,"OK","확인") -> OK | L38: =IF($J38="","-",IF(COUNTIFS($J$2:$J$171,$J38,$B$2:$B$171,$B38)=COUNTIF($J$2:$J$171,$J38),"OK","확인")) -> OK
A39: 38 | B39: SADNESS | C39: Guerlin Leborgne | D39: 2026318745 | E39: M | F39: M | G39: Seoul | K39: =IF(COUNTIF('팀별_명단'!$A$5:$W$34,$C39)=1,"OK","확인") -> OK | L39: =IF($J39="","-",IF(COUNTIFS($J$2:$J$171,$J39,$B$2:$B$171,$B39)=COUNTIF($J$2:$J$171,$J39),"OK","확인")) -> -
A40: 39 | B40: SADNESS | C40: Henry Boyle | D40: 2026318912 | E40: M | F40: L | G40: Seoul | I40: Josef Hofvenstam | J40: 114 | K40: =IF(COUNTIF('팀별_명단'!$A$5:$W$34,$C40)=1,"OK","확인") -> OK | L40: =IF($J40="","-",IF(COUNTIFS($J$2:$J$171,$J40,$B$2:$B$171,$B40)=COUNTIF($J$2:$J$171,$J40),"OK","확인")) -> OK
...

Sheet 팀별_명단
A1: TEAM JOY | E1: TEAM SADNESS | I1: TEAM ANGER | M1: TEAM DISGUST | Q1: TEAM FEAR | U1: TEAM ANXIETY
A2: 총원 | B2: =COUNTA(A5:A34) -> 29 | E2: 총원 | F2: =COUNTA(E5:E34) -> 28 | I2: 총원 | J2: =COUNTA(I5:I34) -> 28 | M2: 총원 | N2: =COUNTA(M5:M34) -> 28 | Q2: 총원 | R2: =COUNTA(Q5:Q34) -> 28 | U2: 총원 | V2: =COUNTA(U5:U34) -> 29
A3: 여 / 남 | B3: =COUNTIF(B5:B34,"F") -> 17 | C3: =COUNTIF(B5:B34,"M") -> 12 | E3: 여 / 남 | F3: =COUNTIF(F5:F34,"F") -> 17 | G3: =COUNTIF(F5:F34,"M") -> 11 | I3: 여 / 남 | J3: =COUNTIF(J5:J34,"F") -> 17 | K3: =COUNTIF(J5:J34,"M") -> 11 | M3: 여 / 남 | N3: =COUNTIF(N5:N34,"F") -> 16 | O3: =COUNTIF(N5:N34,"M") -> 12 | Q3: 여 / 남 | R3: =COUNTIF(R5:R34,"F") -> 17 | S3: =COUNTIF(R5:R34,"M") -> 11 | U3: 여 / 남 | V3: =COUNTIF(V5:V34,"F") -> 17 | W3: =COUNTIF(V5:V34,"M") -> 12
A4: 이름 | B4: 성별 | C4: 티셔츠 | E4: 이름 | F4: 성별 | G4: 티셔츠 | I4: 이름 | J4: 성별 | K4: 티셔츠 | M4: 이름 | N4: 성별 | O4: 티셔츠 | Q4: 이름 | R4: 성별 | S4: 티셔츠 | U4: 이름 | V4: 성별 | W4: 티셔츠
A5: Abdallah Alhamidi | B5: M | C5: L | E5: Aaron Dumlao | F5: M | G5: L | I5: Caleb Snow | J5: M | K5: M | M5: Alexander Brand | N5: M | O5: L | Q5: Alicia Zimmermann | R5: F | S5: M | U5: Adedoyin Hannah Bajulaiye | V5: F | W5: M
A6: Alberto Gil Carvalho | B6: M | C6: M | E6: Alessandro Noia | F6: M | G6: M | I6: Carina Chin | J6: F | K6: M | M6: Andrea Nordbaeck | N6: F | O6: L | Q6: Amber Allen | R6: F | S6: L | U6: Aybike Saricay | V6: F | W6: L
A7: Alexandra Becker | B7: F | C7: L | E7: Alice Nicoli | F7: F | G7: M | I7: Christina Xing Min Chen | J7: F | K7: L | M7: Andrew White | N7: M | O7: 2XL | Q7: Cameron Rodwell | R7: M | S7: M | U7: Boaz Verbeek | V7: M | W7: 3XL
A8: Artyom Tsoy | B8: M | C8: L | E8: Amber Mae Britchford | F8: F | G8: M | I8: Cristina Toso | J8: F | K8: M | M8: Anita Shani Hufnagl | N8: F | O8: M | Q8: Chaimae Ait Lemzend | R8: F | S8: M | U8: Caroline Borko | V8: F | W8: L
A9: Beatriz Costa | B9: F | C9: M | E9: Anika Dartsch | F9: F | G9: M | I9: Dante Butler | J9: M | K9: 2XL | M9: Apiou Jade | N9: F | O9: M | Q9: Dylan Ian Broderick | R9: M | S9: XL | U9: Deni Elembaev | V9: M | W9: M
A10: Ben Daniel Gerhard Murrmann | B10: M | C10: XL | E10: Augustin Kuntz | F10: M | G10: M | I10: Derry Fernaldy | J10: M | K10: XL | M10: Asmira Tleuova | N10: F | O10: L | Q10: Essence White | R10: F | S10: 3XL | U10: Diana Escalante Garcia | V10: F | W10: M
A11: Boglarka Peter | B11: F | C11: S | E11: Farouk Ousseini | F11: M | G11: L | I11: Evelyn Grace Begent | J11: F | K11: M | M11: Carina von Deyn | N11: F | O11: S | Q11: Giacomo Vernucci | R11: M | S11: XL | U11: Edoardo De Bettin | V11: M | W11: XL
A12: Carla Mas Juncosa | B12: F | C12: L | E12: Faruk Husovic | F12: M | G12: L | I12: Gero Bresgen | J12: M | K12: XL | M12: Christiaan van Olst | N12: M | O12: 2XL | Q12: Haendel Johannes | R12: M | S12: L | U12: Frieda Pollmann | V12: F | W12: M
A13: Eeva Joensuu | B13: F | C13: L | E13: Guerlin Leborgne | F13: M | G13: M | I13: Hardy Benjamin Louis | J13: M | K13: L | M13: Corey Cooper | N13: M | O13: XL | Q13: Hanna Maria Wild | R13: F | S13: L | U13: Gaia Bolcato | V13: F | W13: M
A14: Ella Heikinheimo | B14: F | C14: L | E14: Henry Boyle | F14: M | G14: L | I14: Ida Trabold | J14: F | K14: M | M14: Daniels Kristapaitis | N14: M | O14: 2XL | Q14: Henna Kinnunen | R14: F | S14: XL | U14: Geicianny Martins | V14: F | W14: L
A15: Finesse Johnson Stewart | B15: F | C15: M | E15: Jasmin Schaefer | F15: F | G15: M | I15: Ivanna Perez Gonzalez | J15: F | K15: L | M15: Elizabeth Kang | N15: F | O15: M | Q15: Holly Waters | R15: F | S15: XL | U15: Hannah Elysha Budding | V15: F | W15: M
... A32: Serafima Pavlova | B32: F | C32: L | E32: Tom Nathanael Paumard | F32: M | G32: M | I32: Valerie Del Campo | J32: F | K32: L | M32: Yosra El Bazoui Lamouaddar | N32: F | O32: M | Q32: Tim Yang | R32: M | S32: L | U32: Weng Lingchih | V32: F | W32: L
A33: Theis Oestergaard Hove | B33: M | C33: XL | U33: Yuliana Alcaraz | V33: F | W33: M

Sheet 집계_검증
A1: 26-2 스포츠데이 팀 배정 집계 (교환학생)
A2: 인사이드 아웃 6팀 · 수금 완료(pay=TRUE) 170명 기준
A4: ■ 팀별 인원 집계
A5: 팀 | B5: 총원 | C5: 여(F) | D5: 남(M) | E5: 여 비율 | F5: S~M | G5: L 이상
A6: TEAM JOY | B6: =COUNTIF('팀배정_전체'!$B$2:$B$171,"JOY") -> 29 | C6: =COUNTIFS('팀배정_전체'!$B$2:$B$171,"JOY",'팀배정_전체'!$E$2:$E$171,"F") -> 17 | D6: =COUNTIFS('팀배정_전체'!$B$2:$B$171,"JOY",'팀배정_전체'!$E$2:$E$171,"M") -> 12 | E6: =IF($B6=0,"",$C6/$B6) -> 0.5862069 | F6: =COUNTIFS('팀배정_전체'!$B$2:$B$171,"JOY",'팀배정_전체'!$F$2:$F$171,"S")+COUNTIFS('팀배정_전체'!$B$2:$B$171,"JOY",'팀배정_전체'!$F$2:$F$171,"M") -> 13 | G6: =$B6-$F6 -> 16
A7: TEAM SADNESS | B7: =COUNTIF('팀배정_전체'!$B$2:$B$171,"SADNESS") -> 28 | C7: =COUNTIFS('팀배정_전체'!$B$2:$B$171,"SADNESS",'팀배정_전체'!$E$2:$E$171,"F") -> 17 | D7: =COUNTIFS('팀배정_전체'!$B$2:$B$171,"SADNESS",'팀배정_전체'!$E$2:$E$171,"M") -> 11 | E7: =IF($B7=0,"",$C7/$B7) -> 0.60714286 | F7: =COUNTIFS('팀배정_전체'!$B$2:$B$171,"SADNESS",'팀배정_전체'!$F$2:$F$171,"S")+COUNTIFS('팀배정_전체'!$B$2:$B$171,"SADNESS",'팀배정_전체'!$F$2:$F$171,"M") -> 17 | G7: =$B7-$F7 -> 11
A8: TEAM ANGER | B8: =COUNTIF('팀배정_전체'!$B$2:$B$171,"ANGER") -> 28 | C8: =COUNTIFS('팀배정_전체'!$B$2:$B$171,"ANGER",'팀배정_전체'!$E$2:$E$171,"F") -> 17 | D8: =COUNTIFS('팀배정_전체'!$B$2:$B$171,"ANGER",'팀배정_전체'!$E$2:$E$171,"M") -> 11 | E8: =IF($B8=0,"",$C8/$B8) -> 0.60714286 | F8: =COUNTIFS('팀배정_전체'!$B$2:$B$171,"ANGER",'팀배정_전체'!$F$2:$F$171,"S")+COUNTIFS('팀배정_전체'!$B$2:$B$171,"ANGER",'팀배정_전체'!$F$2:$F$171,"M") -> 12 | G8: =$B8-$F8 -> 16
A9: TEAM DISGUST | B9: =COUNTIF('팀배정_전체'!$B$2:$B$171,"DISGUST") -> 28 | C9: =COUNTIFS('팀배정_전체'!$B$2:$B$171,"DISGUST",'팀배정_전체'!$E$2:$E$171,"F") -> 16 | D9: =COUNTIFS('팀배정_전체'!$B$2:$B$171,"DISGUST",'팀배정_전체'!$E$2:$E$171,"M") -> 12 | E9: =IF($B9=0,"",$C9/$B9) -> 0.57142857 | F9: =COUNTIFS('팀배정_전체'!$B$2:$B$171,"DISGUST",'팀배정_전체'!$F$2:$F$171,"S")+COUNTIFS('팀배정_전체'!$B$2:$B$171,"DISGUST",'팀배정_전체'!$F$2:$F$171,"M") -> 14 | G9: =$B9-$F9 -> 14
A10: TEAM FEAR | B10: =COUNTIF('팀배정_전체'!$B$2:$B$171,"FEAR") -> 28 | C10: =COUNTIFS('팀배정_전체'!$B$2:$B$171,"FEAR",'팀배정_전체'!$E$2:$E$171,"F") -> 17 | D10: =COUNTIFS('팀배정_전체'!$B$2:$B$171,"FEAR",'팀배정_전체'!$E$2:$E$171,"M") -> 11 | E10: =IF($B10=0,"",$C10/$B10) -> 0.60714286 | F10: =COUNTIFS('팀배정_전체'!$B$2:$B$171,"FEAR",'팀배정_전체'!$F$2:$F$171,"S")+COUNTIFS('팀배정_전체'!$B$2:$B$171,"FEAR",'팀배정_전체'!$F$2:$F$171,"M") -> 8 | G10: =$B10-$F10 -> 20
A11: TEAM ANXIETY | B11: =COUNTIF('팀배정_전체'!$B$2:$B$171,"ANXIETY") -> 29 | C11: =COUNTIFS('팀배정_전체'!$B$2:$B$171,"ANXIETY",'팀배정_전체'!$E$2:$E$171,"F") -> 17 | D11: =COUNTIFS('팀배정_전체'!$B$2:$B$171,"ANXIETY",'팀배정_전체'!$E$2:$E$171,"M") -> 12 | E11: =IF($B11=0,"",$C11/$B11) -> 0.5862069 | F11: =COUNTIFS('팀배정_전체'!$B$2:$B$171,"ANXIETY",'팀배정_전체'!$F$2:$F$171,"S")+COUNTIFS('팀배정_전체'!$B$2:$B$171,"ANXIETY",'팀배정_전체'!$F$2:$F$171,"M") -> 13 | G11: =$B11-$F11 -> 16
A12: 합계 | B12: =SUM(B6:B11) -> 170 | C12: =SUM(C6:C11) -> 101 | D12: =SUM(D6:D11) -> 69 | E12: =IF($B12=0,"",$C12/$B12) -> 0.59411765 | F12: =SUM(F6:F11) -> 77 | G12: =SUM(G6:G11) -> 93
A15: ■ 검증 (모두 OK 여야 함)
A16: 검증 항목 | B16: 결과 | C16: 판정
A17: 전체 응답 인원 (팀배정_전체 행 수) | B17: =COUNTA('팀배정_전체'!$C$2:$C$171) -> 170 | C17: =IF($B17=170,"OK","확인") -> OK
A18: 팀 배정 인원 합계 | B18: =SUM($B6:$B11) -> 170 | C18: =IF($B18=$B17,"OK","확인") -> OK
A19: 팀 미배정(빈칸) 인원 | B19: =COUNTBLANK('팀배정_전체'!$B$2:$B$171) -> 0 | C19: =IF($B19=0,"OK","확인") -> OK
A20: 이름 중복 건수 | B20: {=SUMPRODUCT(('팀배정_전체'!$C$2:$C$171<>"")*(COUNTIF('팀배정_전체'!$C$2:$C$171,'팀배정_전체'!$C$2:$C$171)>1))} -> 0 | C20: =IF($B20=0,"OK","확인") -> OK
A21: 학번 중복 건수 | B21: {=SUMPRODUCT(('팀배정_전체'!$D$2:$D$171<>"")*(COUNTIF('팀배정_전체'!$D$2:$D$171,'팀배정_전체'!$D$2:$D$171)>1))} -> 0 | C21: =IF($B21=0,"OK","확인") -> OK
A22: 학번 자릿수 이상(10자리 아님) | B22: =SUMPRODUCT((LEN('팀배정_전체'!$D$2:$D$171)<>10)*1) -> 0 | C22: =IF($B22=0,"OK","확인") -> OK
A23: 팀별_명단 총 인원 | B23: =COUNTA('팀별_명단'!$A$5:$A$34)+COUNTA('팀별_명단'!$E$5:$E$34)+COUNTA('팀별_명단'!$I$5:$I$34)+COUNTA('팀별_명단'!$M$5:$M$34)+COUNTA('팀별_명단'!$Q$5:$Q$34)+COUNTA('팀별_명단'!$U$5:$U$34) -> 170 | C23: =IF($B23=$B17,"OK","확인") -> OK
A24: 두 시트 간 이름 누락/중복 건수 | B24: =COUNTIF('팀배정_전체'!$K$2:$K$171,"확인") -> 0 | C24: =IF($B24=0,"OK","확인") -> OK
A25: 최대-최소 팀 인원 차 | B25: =MAX($B6:$B11)-MIN($B6:$B11) -> 1 | C25: =IF($B25<=1,"OK","확인") -> OK
A26: 최대-최소 팀 여성 인원 차 | B26: =MAX($C6:$C11)-MIN($C6:$C11) -> 1 | C26: =IF($B26<=2,"OK","확인") -> OK
A27: 친구 그룹 분리 건수 | B27: =COUNTIF('팀배정_전체'!$L$2:$L$171,"확인") -> 0 | C27: =IF($B27=0,"OK","확인") -> OK
A28: 친구 요청 반영 인원 | B28: =SUMPRODUCT(('팀배정_전체'!$J$2:$J$171<>"")*1) -> 92 | C28: =IF($B28>0,"OK","확인") -> OK
A30: ■ 티셔츠 사이즈 집계 (전체)
A31: 사이즈 | B31: S | C31: M | D31: L | E31: XL | F31: 2XL | G31: 3XL | H31: 합계
A32: 인원 | B32: =COUNTIF('팀배정_전체'!$F$2:$F$171,"S") -> 17 | C32: =COUNTIF('팀배정_전체'!$F$2:$F$171,"M") -> 60 | D32: =COUNTIF('팀배정_전체'!$F$2:$F$171,"L") -> 56 | E32: =COUNTIF('팀배정_전체'!$F$2:$F$171,"XL") -> 21 | F32: =COUNTIF('팀배정_전체'!$F$2:$F$171,"2XL") -> 11 | G32: =COUNTIF('팀배정_전체'!$F$2:$F$171,"3XL") -> 5 | H32: =SUM(B32:G32) -> 170
A34: ■ 출발지 집계 (버스 80석 확인용)
A35: Seoul Campus (버스) | B35: =COUNTIF('팀배정_전체'!$G$2:$G$171,"Seoul") -> 128
A36: Suwon Campus (현장 집합) | B36: =COUNTIF('팀배정_전체'!$G$2:$G$171,"Suwon") -> 42
A37: 버스 정원(80) 초과 인원 | B37: =MAX(0,$B35-80) -> 48
A39: ■ 수동 확인 필요
A40: 대상 | B40: 내용
A41: 미납 제외 | B41: 수금부스 pay=FALSE 10명을 명단에서 제외함: Jennifer Parathithasan, Emerald Trinh (취소 - 인스타 디엠), Yeonseo Jo (수금표 학번 미기재), Trinh Ngoc Thuc Anh, Nazel Goersoy, Mortada Guesmia, Emil Tenhagen (인스타 디엠 보내놓음), Cassandra Brandner (취소 - 인스타 연락), Lorick Forest, Tobias Sejling Tops
A42: 2026318785 | B42: 연락처 새로 남겨주심 (gero.bresgen@gmx.de / +49 15159401074), 기존 컨택 방법 없음
A43: 2026318971 | B43: 학번 정정: 202631897 → 2026318971
A44: 2026318973 | B44: 티셔츠 L → 2XL 변경
A45: 2026318759 | B45: 티셔츠 L → M 변경
A46: 2026318578 | B46: 이름 확인: Sofia Feucetti (폼 이메일은 Felicetti)
...
